Workbook

Sheet Set recomendado
A1: Jugador | B1: Tipo de Slot | C1: Prioridad
A2: Hoshiumi | B2: Poder vibrante | C2: 1
A3: Hoshiumi | B3: Incremento de poder | C3: 2
A4: Hoshiumi | B4: Potenciación de la moral | C4: 3
A5: Hoshiumi | B5: Opt. de estado | C5: 4
A6: Kyotani | B6: Poder vibrante | C6: 1
A7: Kyotani | B7: Incremento de poder | C7: 2
A8: Kyotani | B8: Potenciación de la moral | C8: 3
A9: Kyotani | B9: Opt. de estado | C9: 4
A10: Iwaizumi | B10: Poder vibrante | C10: 1
A11: Iwaizumi | B11: Incremento de poder | C11: 2
A12: Iwaizumi | B12: Potenciación de la moral | C12: 3
A13: Iwaizumi | B13: Opt. de estado | C13: 4
... A58: Yamamoto | B58: Opt. de estado | C58: 4

Sheet Stats recomendados
A1: Jugador | B1: Puntos | C1: Substats
A2: Hoshiumi | B2: 4 | C2: Ataque poderoso
A3: Hoshiumi | B3: 3 | C3: Percepción
A4: Hoshiumi | B4: 3 | C4: Fuerza
A5: Hoshiumi | B5: 2 | C5: Técnica ofensiva
A6: Hoshiumi | B6: 1 | C6: Saque
A7: Hoshiumi | B7: 1 | C7: Bloqueo
A8: Hoshiumi | B8: 1 | C8: Recepción
A9: Kyotani | B9: 4 | C9: Ataque poderoso
A10: Kyotani | B10: 3 | C10: Saque
A11: Kyotani | B11: 2 | C11: Percepción
A12: Kyotani | B12: 2 | C12: Fuerza
A13: Kyotani | B13: 1 | C13: Técnica ofensiva
... A122: Yamamoto | B122: 1 | C122: Espíritu

Sheet Inventario1
A1: ID | B1: Calidad | C1: Tipo | D1: Main Stat | E1: Substat1 | F1: Substat2 | G1: Substat3 | H1: Substat4 | I1: Estado Act | J1: Jugador
A2: 1 | B2: Legendario | C2: Pase preciso | D2: Colocación | E2: Recepción | F2: Saque | G2: Ataque rápido | H2: Fuerza | I2: =IF(ISNUMBER(A2), IF(COUNTIFS(Equipar!B:B,1,Equipar!AC:AC,A2),"Equipada", IF( OR(COUNTIFS(Equipar!B:B,1,Equipar!C:C,A2) +COUNTIFS(Equipar!B:B,1,Equipar!D:D,A2) +COUNTIFS(Equipar!B:B,1,Equipar!E:E,A2) +COUNTIFS(Equipar!B:B,1,Equipar!F:F,A2) >0,COUNTIF('Set recomendado'!B:B,C2)=0), "Bloqueada", "Desechable")),"" ) -> Equipada | J2: {=IF(ISNUMBER(A2),IFERROR(_xlfn._xlws.FILTER(Equipar!A:A,(Equipar!B:B=1)*(Equipar!AC:AC=A2)),""),"")} -> Oikawa
A3: 2 | B3: Legendario | C3: Poder vibrante | D3: Ataque poderoso | E3: Recepción | F3: Ataque rápido | G3: Recepción | H3: Técnica ofensiva | I3: =IF(ISNUMBER(A3), IF(COUNTIFS(Equipar!B:B,1,Equipar!AC:AC,A3),"Equipada", IF( OR(COUNTIFS(Equipar!B:B,1,Equipar!C:C,A3) +COUNTIFS(Equipar!B:B,1,Equipar!D:D,A3) +COUNTIFS(Equipar!B:B,1,Equipar!E:E,A3) +COUNTIFS(Equipar!B:B,1,Equipar!F:F,A3) >0,COUNTIF('Set recomendado'!B:B,C3)=0), "Bloqueada", "Desechable")),"" ) -> Equipada | J3: {=IF(ISNUMBER(A3),IFERROR(_xlfn._xlws.FILTER(Equipar!A:A,(Equipar!B:B=1)*(Equipar!AC:AC=A3)),""),"")} -> Sakusa
A4: 3 | B4: Legendario | C4: Poder vibrante | D4: Ataque poderoso | E4: Ataque poderoso | F4: Ataque rápido | G4: Recepción | H4: Recuperación | I4: =IF(ISNUMBER(A4), IF(COUNTIFS(Equipar!B:B,1,Equipar!AC:AC,A4),"Equipada", IF( OR(COUNTIFS(Equipar!B:B,1,Equipar!C:C,A4) +COUNTIFS(Equipar!B:B,1,Equipar!D:D,A4) +COUNTIFS(Equipar!B:B,1,Equipar!E:E,A4) +COUNTIFS(Equipar!B:B,1,Equipar!F:F,A4) >0,COUNTIF('Set recomendado'!B:B,C4)=0), "Bloqueada", "Desechable")),"" ) -> Equipada | J4: {=IF(ISNUMBER(A4),IFERROR(_xlfn._xlws.FILTER(Equipar!A:A,(Equipar!B:B=1)*(Equipar!AC:AC=A4)),""),"")} -> Tanaka
A5: 4 | B5: Legendario | C5: Incremento de poder | D5: Ataque poderoso | E5: Bloqueo | F5: Saque | G5: Saque | H5: Fuerza | I5: =IF(ISNUMBER(A5), IF(COUNTIFS(Equipar!B:B,1,Equipar!AC:AC,A5),"Equipada", IF( OR(COUNTIFS(Equipar!B:B,1,Equipar!C:C,A5) +COUNTIFS(Equipar!B:B,1,Equipar!D:D,A5) +COUNTIFS(Equipar!B:B,1,Equipar!E:E,A5) +COUNTIFS(Equipar!B:B,1,Equipar!F:F,A5) >0,COUNTIF('Set recomendado'!B:B,C5)=0), "Bloqueada", "Desechable")),"" ) -> Equipada | J5: {=IF(ISNUMBER(A5),IFERROR(_xlfn._xlws.FILTER(Equipar!A:A,(Equipar!B:B=1)*(Equipar!AC:AC=A5)),""),"")} -> Hoshiumi
A6: 5 | B6: Legendario | C6: Bloque preciso | D6: Bloqueo | E6: Bloqueo | F6: Colocación | G6: Ataque rápido | H6: Ataque rápido | I6: =IF(ISNUMBER(A6), IF(COUNTIFS(Equipar!B:B,1,Equipar!AC:AC,A6),"Equipada", IF( OR(COUNTIFS(Equipar!B:B,1,Equipar!C:C,A6) +COUNTIFS(Equipar!B:B,1,Equipar!D:D,A6) +COUNTIFS(Equipar!B:B,1,Equipar!E:E,A6) +COUNTIFS(Equipar!B:B,1,Equipar!F:F,A6) >0,COUNTIF('Set recomendado'!B:B,C6)=0), "Bloqueada", "Desechable")),"" ) -> Equipada | J6: {=IF(ISNUMBER(A6),IFERROR(_xlfn._xlws.FILTER(Equipar!A:A,(Equipar!B:B=1)*(Equipar!AC:AC=A6)),""),"")} -> Hirugami
A7: 6 | B7: Legendario | C7: Opt. de percepción | D7: Ataque rápido | E7: Ataque poderoso | F7: Recepción | G7: Percepción | H7: Saque | I7: =IF(ISNUMBER(A7), IF(COUNTIFS(Equipar!B:B,1,Equipar!AC:AC,A7),"Equipada", IF( OR(COUNTIFS(Equipar!B:B,1,Equipar!C:C,A7) +COUNTIFS(Equipar!B:B,1,Equipar!D:D,A7) +COUNTIFS(Equipar!B:B,1,Equipar!E:E,A7) +COUNTIFS(Equipar!B:B,1,Equipar!F:F,A7) >0,COUNTIF('Set recomendado'!B:B,C7)=0), "Bloqueada", "Desechable")),"" ) -> Bloqueada | J7: {=IF(ISNUMBER(A7),IFERROR(_xlfn._xlws.FILTER(Equipar!A:A,(Equipar!B:B=1)*(Equipar!AC:AC=A7)),""),"")}
A8: 7 | B8: Legendario | C8: Opt. de percepción | D8: Ataque rápido | E8: Recuperación | F8: Saque | G8: Recuperación | I8: =IF(ISNUMBER(A8), IF(COUNTIFS(Equipar!B:B,1,Equipar!AC:AC,A8),"Equipada", IF( OR(COUNTIFS(Equipar!B:B,1,Equipar!C:C,A8) +COUNTIFS(Equipar!B:B,1,Equipar!D:D,A8) +COUNTIFS(Equipar!B:B,1,Equipar!E:E,A8) +COUNTIFS(Equipar!B:B,1,Equipar!F:F,A8) >0,COUNTIF('Set recomendado'!B:B,C8)=0), "Bloqueada", "Desechable")),"" ) -> Bloqueada | J8: {=IF(ISNUMBER(A8),IFERROR(_xlfn._xlws.FILTER(Equipar!A:A,(Equipar!B:B=1)*(Equipar!AC:AC=A8)),""),"")}
A9: 8 | B9: Legendario | C9: Guardia contundente | D9: Bloqueo | E9: Bloqueo | F9: Colocación | G9: Saque | I9: =IF(ISNUMBER(A9), IF(COUNTIFS(Equipar!B:B,1,Equipar!AC:AC,A9),"Equipada", IF( OR(COUNTIFS(Equipar!B:B,1,Equipar!C:C,A9) +COUNTIFS(Equipar!B:B,1,Equipar!D:D,A9) +COUNTIFS(Equipar!B:B,1,Equipar!E:E,A9) +COUNTIFS(Equipar!B:B,1,Equipar!F:F,A9) >0,COUNTIF('Set recomendado'!B:B,C9)=0), "Bloqueada", "Desechable")),"" ) -> Desechable | J9: {=IF(ISNUMBER(A9),IFERROR(_xlfn._xlws.FILTER(Equipar!A:A,(Equipar!B:B=1)*(Equipar!AC:AC=A9)),""),"")}
A10: 9 | B10: Legendario | C10: Pase preciso | D10: Colocación | E10: Ataque rápido | F10: Fuerza | G10: Recuperación | I10: =IF(ISNUMBER(A10), IF(COUNTIFS(Equipar!B:B,1,Equipar!AC:AC,A10),"Equipada", IF( OR(COUNTIFS(Equipar!B:B,1,Equipar!C:C,A10) +COUNTIFS(Equipar!B:B,1,Equipar!D:D,A10) +COUNTIFS(Equipar!B:B,1,Equipar!E:E,A10) +COUNTIFS(Equipar!B:B,1,Equipar!F:F,A10) >0,COUNTIF('Set recomendado'!B:B,C10)=0), "Bloqueada", "Desechable")),"" ) -> Desechable | J10: {=IF(ISNUMBER(A10),IFERROR(_xlfn._xlws.FILTER(Equipar!A:A,(Equipar!B:B=1)*(Equipar!AC:AC=A10)),""),"")}
A11: 10 | B11: Legendario | C11: Pase preciso | D11: Colocación | E11: Ataque poderoso | F11: Colocación | G11: Técnica ofensiva | I11: =IF(ISNUMBER(A11), IF(COUNTIFS(Equipar!B:B,1,Equipar!AC:AC,A11),"Equipada", IF( OR(COUNTIFS(Equipar!B:B,1,Equipar!C:C,A11) +COUNTIFS(Equipar!B:B,1,Equipar!D:D,A11) +COUNTIFS(Equipar!B:B,1,Equipar!E:E,A11) +COUNTIFS(Equipar!B:B,1,Equipar!F:F,A11) >0,COUNTIF('Set recomendado'!B:B,C11)=0), "Bloqueada", "Desechable")),"" ) -> Bloqueada | J11: {=IF(ISNUMBER(A11),IFERROR(_xlfn._xlws.FILTER(Equipar!A:A,(Equipar!B:B=1)*(Equipar!AC:AC=A11)),""),"")}
A12: 11 | B12: Legendario | C12: Poder vibrante | D12: Ataque poderoso | E12: Recuperación | F12: Percepción | G12: Bloqueo | H12: Ataque rápido | I12: =IF(ISNUMBER(A12), IF(COUNTIFS(Equipar!B:B,1,Equipar!AC:AC,A12),"Equipada", IF( OR(COUNTIFS(Equipar!B:B,1,Equipar!C:C,A12) +COUNTIFS(Equipar!B:B,1,Equipar!D:D,A12) +COUNTIFS(Equipar!B:B,1,Equipar!E:E,A12) +COUNTIFS(Equipar!B:B,1,Equipar!F:F,A12) >0,COUNTIF('Set recomendado'!B:B,C12)=0), "Bloqueada", "Desechable")),"" ) -> Desechable | J12: {=IF(ISNUMBER(A12),IFERROR(_xlfn._xlws.FILTER(Equipar!A:A,(Equipar!B:B=1)*(Equipar!AC:AC=A12)),""),"")}
A13: 12 | B13: Legendario | C13: Poder vibrante | D13: Ataque poderoso | E13: Recuperación | F13: Saque | G13: Técnica defensiva | I13: =IF(ISNUMBER(A13), IF(COUNTIFS(Equipar!B:B,1,Equipar!AC:AC,A13),"Equipada", IF( OR(COUNTIFS(Equipar!B:B,1,Equipar!C:C,A13) +COUNTIFS(Equipar!B:B,1,Equipar!D:D,A13) +COUNTIFS(Equipar!B:B,1,Equipar!E:E,A13) +COUNTIFS(Equipar!B:B,1,Equipar!F:F,A13) >0,COUNTIF('Set recomendado'!B:B,C13)=0), "Bloqueada", "Desechable")),"" ) -> Desechable | J13: {=IF(ISNUMBER(A13),IFERROR(_xlfn._xlws.FILTER(Equipar!A:A,(Equipar!B:B=1)*(Equipar!AC:AC=A13)),""),"")}
A14: 13 | B14: Legendario | C14: Incremento de poder | D14: Ataque poderoso | E14: Ataque rápido | F14: Espíritu | G14: Saque | I14: =IF(ISNUMBER(A14), IF(COUNTIFS(Equipar!B:B,1,Equipar!AC:AC,A14),"Equipada", IF( OR(COUNTIFS(Equipar!B:B,1,Equipar!C:C,A14) +COUNTIFS(Equipar!B:B,1,Equipar!D:D,A14) +COUNTIFS(Equipar!B:B,1,Equipar!E:E,A14) +COUNTIFS(Equipar!B:B,1,Equipar!F:F,A14) >0,COUNTIF('Set recomendado'!B:B,C14)=0), "Bloqueada", "Desechable")),"" ) -> Desechable | J14: {=IF(ISNUMBER(A14),IFERROR(_xlfn._xlws.FILTER(Equipar!A:A,(Equipar!B:B=1)*(Equipar!AC:AC=A14)),""),"")}
A15: 14 | B15: Legendario | C15: Incremento de poder | D15: Ataque poderoso | E15: Recuperación | F15: Colocación | G15: Bloqueo | I15: =IF(ISNUMBER(A15), IF(COUNTIFS(Equipar!B:B,1,Equipar!AC:AC,A15),"Equipada", IF( OR(COUNTIFS(Equipar!B:B,1,Equipar!C:C,A15) +COUNTIFS(Equipar!B:B,1,Equipar!D:D,A15) +COUNTIFS(Equipar!B:B,1,Equipar!E:E,A15) +COUNTIFS(Equipar!B:B,1,Equipar!F:F,A15) >0,COUNTIF('Set recomendado'!B:B,C15)=0), "Bloqueada", "Desechable")),"" ) -> Desechable | J15: {=IF(ISNUMBER(A15),IFERROR(_xlfn._xlws.FILTER(Equipar!A:A,(Equipar!B:B=1)*(Equipar!AC:AC=A15)),""),"")}
A16: 15 | B16: Legendario | C16: Incremento de poder | D16: Ataque poderoso | E16: Saque | F16: Bloqueo | G16: Espíritu | I16: =IF(ISNUMBER(A16), IF(COUNTIFS(Equipar!B:B,1,Equipar!AC:AC,A16),"Equipada", IF( OR(COUNTIFS(Equipar!B:B,1,Equipar!C:C,A16) +COUNTIFS(Equipar!B:B,1,Equipar!D:D,A16) +COUNTIFS(Equipar!B:B,1,Equipar!E:E,A16) +COUNTIFS(Equipar!B:B,1,Equipar!F:F,A16) >0,COUNTIF('Set recomendado'!B:B,C16)=0), "Bloqueada", "Desechable")),"" ) -> Desechable | J16: {=IF(ISNUMBER(A16),IFERROR(_xlfn._xlws.FILTER(Equipar!A:A,(Equipar!B:B=1)*(Equipar!AC:AC=A16)),""),"")}
A17: 16 | B17: Legendario | C17: Ataque veloz | D17: Ataque rápido | E17: Reflejos | F17: Saque | G17: Fuerza | H17: Recuperación | I17: =IF(ISNUMBER(A17), IF(COUNTIFS(Equipar!B:B,1,Equipar!AC:AC,A17),"Equipada", IF( OR(COUNTIFS(Equipar!B:B,1,Equipar!C:C,A17) +COUNTIFS(Equipar!B:B,1,Equipar!D:D,A17) +COUNTIFS(Equipar!B:B,1,Equipar!E:E,A17) +COUNTIFS(Equipar!B:B,1,Equipar!F:F,A17) >0,COUNTIF('Set recomendado'!B:B,C17)=0), "Bloqueada", "Desechable")),"" ) -> Desechable | J17: {=IF(ISNUMBER(A17),IFERROR(_xlfn._xlws.FILTER(Equipar!A:A,(Equipar!B:B=1)*(Equipar!AC:AC=A17)),""),"")}
A18: 17 | B18: Legendario | C18: Sentido agudo | D18: Ataque rápido | E18: Técnica ofensiva | F18: Ataque poderoso | G18: Recuperación | H18: Bloqueo | I18: =IF(ISNUMBER(A18), IF(COUNTIFS(Equipar!B:B,1,Equipar!AC:AC,A18),"Equipada", IF( OR(COUNTIFS(Equipar!B:B,1,Equipar!C:C,A18) +COUNTIFS(Equipar!B:B,1,Equipar!D:D,A18) +COUNTIFS(Equipar!B:B,1,Equipar!E:E,A18) +COUNTIFS(Equipar!B:B,1,Equipar!F:F,A18) >0,COUNTIF('Set recomendado'!B:B,C18)=0), "Bloqueada", "Desechable")),"" ) -> Bloqueada | J18: {=IF(ISNUMBER(A18),IFERROR(_xlfn._xlws.FILTER(Equipar!A:A,(Equipar!B:B=1)*(Equipar!AC:AC=A18)),""),"")}
A19: 18 | B19: Legendario | C19: Sentido agudo | D19: Ataque rápido | E19: Percepción | F19: Saque | G19: Recepción | I19: =IF(ISNUMBER(A19), IF(COUNTIFS(Equipar!B:B,1,Equipar!AC:AC,A19),"Equipada", IF( OR(COUNTIFS(Equipar!B:B,1,Equipar!C:C,A19) +COUNTIFS(Equipar!B:B,1,Equipar!D:D,A19) +COUNTIFS(Equipar!B:B,1,Equipar!E:E,A19) +COUNTIFS(Equipar!B:B,1,Equipar!F:F,A19) >0,COUNTIF('Set recomendado'!B:B,C19)=0), "Bloqueada", "Desechable")),"" ) -> Desechable | J19: {=IF(ISNUMBER(A19),IFERROR(_xlfn._xlws.FILTER(Equipar!A:A,(Equipar!B:B=1)*(Equipar!AC:AC=A19)),""),"")}
A20: 19 | B20: Legendario | C20: Sentido agudo | D20: Ataque rápido | E20: Bloqueo | F20: Saque | G20: Ataque rápido | I20: =IF(ISNUMBER(A20), IF(COUNTIFS(Equipar!B:B,1,Equipar!AC:AC,A20),"Equipada", IF( OR(COUNTIFS(Equipar!B:B,1,Equipar!C:C,A20) +COUNTIFS(Equipar!B:B,1,Equipar!D:D,A20) +COUNTIFS(Equipar!B:B,1,Equipar!E:E,A20) +COUNTIFS(Equipar!B:B,1,Equipar!F:F,A20) >0,COUNTIF('Set recomendado'!B:B,C20)=0), "Bloqueada", "Desechable")),"" ) -> Equipada | J20: {=IF(ISNUMBER(A20),IFERROR(_xlfn._xlws.FILTER(Equipar!A:A,(Equipar!B:B=1)*(Equipar!AC:AC=A20)),""),"")} -> Hinata
A21: 20 | B21: Legendario | C21: Bloque preciso | D21: Bloqueo | E21: Saque | F21: Bloqueo | G21: Ataque poderoso | I21: =IF(ISNUMBER(A21), IF(COUNTIFS(Equipar!B:B,1,Equipar!AC:AC,A21),"Equipada", IF( OR(COUNTIFS(Equipar!B:B,1,Equipar!C:C,A21) +COUNTIFS(Equipar!B:B,1,Equipar!D:D,A21) +COUNTIFS(Equipar!B:B,1,Equipar!E:E,A21) +COUNTIFS(Equipar!B:B,1,Equipar!F:F,A21) >0,COUNTIF('Set recomendado'!B:B,C21)=0), "Bloqueada", "Desechable")),"" ) -> Equipada | J21: {=IF(ISNUMBER(A21),IFERROR(_xlfn._xlws.FILTER(Equipar!A:A,(Equipar!B:B=1)*(Equipar!AC:AC=A21)),""),"")} -> Suna
A22: 21 | B22: Legendario | C22: Bloque preciso | D22: Bloqueo | E22: Fuerza | F22: Colocación | G22: Saque | I22: =IF(ISNUMBER(A22), IF(COUNTIFS(Equipar!B:B,1,Equipar!AC:AC,A22),"Equipada", IF( OR(COUNTIFS(Equipar!B:B,1,Equipar!C:C,A22) +COUNTIFS(Equipar!B:B,1,Equipar!D:D,A22) +COUNTIFS(Equipar!B:B,1,Equipar!E:E,A22) +COUNTIFS(Equipar!B:B,1,Equipar!F:F,A22) >0,COUNTIF('Set recomendado'!B:B,C22)=0), "Bloqueada", "Desechable")),"" ) -> Desechable | J22: {=IF(ISNUMBER(A22),IFERROR(_xlfn._xlws.FILTER(Equipar!A:A,(Equipar!B:B=1)*(Equipar!AC:AC=A22)),""),"")}
A23: 22 | B23: Legendario | C23: Bloque preciso | D23: Bloqueo | E23: Bloqueo | F23: Espíritu | G23: Recepción | I23: =IF(ISNUMBER(A23), IF(COUNTIFS(Equipar!B:B,1,Equipar!AC:AC,A23),"Equipada", IF( OR(COUNTIFS(Equipar!B:B,1,Equipar!C:C,A23) +COUNTIFS(Equipar!B:B,1,Equipar!D:D,A23) +COUNTIFS(Equipar!B:B,1,Equipar!E:E,A23) +COUNTIFS(Equipar!B:B,1,Equipar!F:F,A23) >0,COUNTIF('Set recomendado'!B:B,C23)=0), "Bloqueada", "Desechable")),"" ) -> Bloqueada | J23: {=IF(ISNUMBER(A23),IFERROR(_xlfn._xlws.FILTER(Equipar!A:A,(Equipar!B:B=1)*(Equipar!AC:AC=A23)),""),"")}
A24: 23 | B24: Legendario | C24: Bloque preciso | D24: Bloqueo | E24: Recuperación | F24: Ataque rápido | G24: Colocación | I24: =IF(ISNUMBER(A24), IF(COUNTIFS(Equipar!B:B,1,Equipar!AC:AC,A24),"Equipada", IF( OR(COUNTIFS(Equipar!B:B,1,Equipar!C:C,A24) +COUNTIFS(Equipar!B:B,1,Equipar!D:D,A24) +COUNTIFS(Equipar!B:B,1,Equipar!E:E,A24) +COUNTIFS(Equipar!B:B,1,Equipar!F:F,A24) >0,COUNTIF('Set recomendado'!B:B,C24)=0), "Bloqueada", "Desechable")),"" ) -> Desechable | J24: {=IF(ISNUMBER(A24),IFERROR(_xlfn._xlws.FILTER(Equipar!A:A,(Equipar!B:B=1)*(Equipar!AC:AC=A24)),""),"")}
A25: 24 | B25: Legendario | C25: Bloque preciso | D25: Bloqueo | E25: Recepción | F25: Bloqueo | G25: Recuperación | I25: =IF(ISNUMBER(A25), IF(COUNTIFS(Equipar!B:B,1,Equipar!AC:AC,A25),"Equipada", IF( OR(COUNTIFS(Equipar!B:B,1,Equipar!C:C,A25) +COUNTIFS(Equipar!B:B,1,Equipar!D:D,A25) +COUNTIFS(Equipar!B:B,1,Equipar!E:E,A25) +COUNTIFS(Equipar!B:B,1,Equipar!F:F,A25) >0,COUNTIF('Set recomendado'!B:B,C25)=0), "Bloqueada", "Desechable")),"" ) -> Desechable | J25: {=IF(ISNUMBER(A25),IFERROR(_xlfn._xlws.FILTER(Equipar!A:A,(Equipar!B:B=1)*(Equipar!AC:AC=A25)),""),"")}
A26: 25 | B26: Legendario | C26: Bloque preciso | D26: Bloqueo | E26: Ataque poderoso | F26: Saque | G26: Colocación | I26: =IF(ISNUMBER(A26), IF(COUNTIFS(Equipar!B:B,1,Equipar!AC:AC,A26),"Equipada", IF( OR(COUNTIFS(Equipar!B:B,1,Equipar!C:C,A26) +COUNTIFS(Equipar!B:B,1,Equipar!D:D,A26) +COUNTIFS(Equipar!B:B,1,Equipar!E:E,A26) +COUNTIFS(Equipar!B:B,1,Equipar!F:F,A26) >0,COUNTIF('Set recomendado'!B:B,C26)=0), "Bloqueada", "Desechable")),"" ) -> Desechable | J26: {=IF(ISNUMBER(A26),IFERROR(_xlfn._xlws.FILTER(Equipar!A:A,(Equipar!B:B=1)*(Equipar!AC:AC=A26)),""),"")}
A27: 26 | B27: Legendario | C27: Movimiento de bloqueo | D27: Bloqueo | E27: Saque | F27: Bloqueo | G27: Ataque rápido | I27: =IF(ISNUMBER(A27), IF(COUNTIFS(Equipar!B:B,1,Equipar!AC:AC,A27),"Equipada", IF( OR(COUNTIFS(Equipar!B:B,1,Equipar!C:C,A27) +COUNTIFS(Equipar!B:B,1,Equipar!D:D,A27) +COUNTIFS(Equipar!B:B,1,Equipar!E:E,A27) +COUNTIFS(Equipar!B:B,1,Equipar!F:F,A27) >0,COUNTIF('Set recomendado'!B:B,C27)=0), "Bloqueada", "Desechable")),"" ) -> Equipada | J27: {=IF(ISNUMBER(A27),IFERROR(_xlfn._xlws.FILTER(Equipar!A:A,(Equipar!B:B=1)*(Equipar!AC:AC=A27)),""),"")} -> Kuroo
A28: 27 | B28: Legendario | C28: Recepción de asistencia | D28: Recepción | E28: Fuerza | F28: Saque | G28: Recepción | H28: Recepción | I28: =IF(ISNUMBER(A28), IF(COUNTIFS(Equipar!B:B,1,Equipar!AC:AC,A28),"Equipada", IF( OR(COUNTIFS(Equipar!B:B,1,Equipar!C:C,A28) +COUNTIFS(Equipar!B:B,1,Equipar!D:D,A28) +COUNTIFS(Equipar!B:B,1,Equipar!E:E,A28) +COUNTIFS(Equipar!B:B,1,Equipar!F:F,A28) >0,COUNTIF('Set recomendado'!B:B,C28)=0), "Bloqueada", "Desechable")),"" ) -> Equipada | J28: {=IF(ISNUMBER(A28),IFERROR(_xlfn._xlws.FILTER(Equipar!A:A,(Equipar!B:B=1)*(Equipar!AC:AC=A28)),""),"")} -> Komori
A29: 28 | B29: Legendario | C29: Recepción de asistencia | D29: Recepción | E29: Ataque poderoso | F29: Ataque poderoso | G29: Bloqueo | H29: Espíritu | I29: =IF(ISNUMBER(A29), IF(COUNTIFS(Equipar!B:B,1,Equipar!AC:AC,A29),"Equipada", IF( OR(COUNTIFS(Equipar!B:B,1,Equipar!C:C,A29) +COUNTIFS(Equipar!B:B,1,Equipar!D:D,A29) +COUNTIFS(Equipar!B:B,1,Equipar!E:E,A29) +COUNTIFS(Equipar!B:B,1,Equipar!F:F,A29) >0,COUNTIF('Set recomendado'!B:B,C29)=0), "Bloqueada", "Desechable")),"" ) -> Equipada | J29: {=IF(ISNUMBER(A29),IFERROR(_xlfn._xlws.FILTER(Equipar!A:A,(Equipar!B:B=1)*(Equipar!AC:AC=A29)),""),"")} -> Kita
A30: 29 | B30: Legendario | C30: Recepción de asistencia | D30: Recepción | E30: Colocación | F30: Técnica ofensiva | G30: Colocación | I30: =IF(ISNUMBER(A30), IF(COUNTIFS(Equipar!B:B,1,Equipar!AC:AC,A30),"Equipada", IF( OR(COUNTIFS(Equipar!B:B,1,Equipar!C:C,A30) +COUNTIFS(Equipar!B:B,1,Equipar!D:D,A30) +COUNTIFS(Equipar!B:B,1,Equipar!E:E,A30) +COUNTIFS(Equipar!B:B,1,Equipar!F:F,A30) >0,COUNTIF('Set recomendado'!B:B,C30)=0), "Bloqueada", "Desechable")),"" ) -> Desechable | J30: {=IF(ISNUMBER(A30),IFERROR(_xlfn._xlws.FILTER(Equipar!A:A,(Equipar!B:B=1)*(Equipar!AC:AC=A30)),""),"")}
A31: 30 | B31: Legendario | C31: Recepción suprema | D31: Recepción | E31: Colocación | F31: Fuerza | G31: Recepción | H31: Ataque rápido | I31: =IF(ISNUMBER(A31), IF(COUNTIFS(Equipar!B:B,1,Equipar!AC:AC,A31),"Equipada", IF( OR(COUNTIFS(Equipar!B:B,1,Equipar!C:C,A31) +COUNTIFS(Equipar!B:B,1,Equipar!D:D,A31) +COUNTIFS(Equipar!B:B,1,Equipar!E:E,A31) +COUNTIFS(Equipar!B:B,1,Equipar!F:F,A31) >0,COUNTIF('Set recomendado'!B:B,C31)=0), "Bloqueada", "Desechable")),"" ) -> Bloqueada | J31: {=IF(ISNUMBER(A31),IFERROR(_xlfn._xlws.FILTER(Equipar!A:A,(Equipar!B:B=1)*(Equipar!AC:AC=A31)),""),"")}
A32: 31 | B32: Legendario | C32: Recepción suprema | D32: Recepción | E32: Ataque poderoso | F32: Bloqueo | G32: Técnica ofensiva | I32: =IF(ISNUMBER(A32), IF(COUNTIFS(Equipar!B:B,1,Equipar!AC:AC,A32),"Equipada", IF( OR(COUNTIFS(Equipar!B:B,1,Equipar!C:C,A32) +COUNTIFS(Equipar!B:B,1,Equipar!D:D,A32) +COUNTIFS(Equipar!B:B,1,Equipar!E:E,A32) +COUNTIFS(Equipar!B:B,1,Equipar!F:F,A32) >0,COUNTIF('Set recomendado'!B:B,C32)=0), "Bloqueada", "Desechable")),"" ) -> Bloqueada | J32: {=IF(ISNUMBER(A32),IFERROR(_xlfn._xlws.FILTER(Equipar!A:A,(Equipar!B:B=1)*(Equipar!AC:AC=A32)),""),"")}
A33: 33 | B33: Legendario | C33: Guardia contundente | D33: Bloqueo | E33: Bloqueo | F33: Ataque poderoso | G33: Colocación | H33: Recuperación | I33: =IF(ISNUMBER(A33), IF(COUNTIFS(Equipar!B:B,1,Equipar!AC:AC,A33),"Equipada", IF( OR(COUNTIFS(Equipar!B:B,1,Equipar!C:C,A33) +COUNTIFS(Equipar!B:B,1,Equipar!D:D,A33) +COUNTIFS(Equipar!B:B,1,Equipar!E:E,A33) +COUNTIFS(Equipar!B:B,1,Equipar!F:F,A33) >0,COUNTIF('Set recomendado'!B:B,C33)=0), "Bloqueada", "Desechable")),"" ) -> Desechable | J33: {=IF(ISNUMBER(A33),IFERROR(_xlfn._xlws.FILTER(Equipar!A:A,(Equipar!B:B=1)*(Equipar!AC:AC=A33)),""),"")}
A34: 34 | B34: Legendario | C34: Opt. de estado | D34: Ataque poderoso | E34: Saque | F34: Reflejos | G34: Recepción | I34: =IF(ISNUMBER(A34), IF(COUNTIFS(Equipar!B:B,1,Equipar!AC:AC,A34),"Equipada", IF( OR(COUNTIFS(Equipar!B:B,1,Equipar!C:C,A34) +COUNTIFS(Equipar!B:B,1,Equipar!D:D,A34) +COUNTIFS(Equipar!B:B,1,Equipar!E:E,A34) +COUNTIFS(Equipar!B:B,1,Equipar!F:F,A34) >0,COUNTIF('Set recomendado'!B:B,C34)=0), "Bloqueada", "Desechable")),"" ) -> Desechable | J34: {=IF(ISNUMBER(A34),IFERROR(_xlfn._xlws.FILTER(Equipar!A:A,(Equipar!B:B=1)*(Equipar!AC:AC=A34)),""),"")}
A35: 35 | B35: Legendario | C35: Opt. de estado | D35: Ataque poderoso | E35: Ataque poderoso | F35: Bloqueo | G35: Espíritu | I35: =IF(ISNUMBER(A35), IF(COUNTIFS(Equipar!B:B,1,Equipar!AC:AC,A35),"Equipada", IF( OR(COUNTIFS(Equipar!B:B,1,Equipar!C:C,A35) +COUNTIFS(Equipar!B:B,1,Equipar!D:D,A35) +COUNTIFS(Equipar!B:B,1,Equipar!E:E,A35) +COUNTIFS(Equipar!B:B,1,Equipar!F:F,A35) >0,COUNTIF('Set recomendado'!B:B,C35)=0), "Bloqueada", "Desechable")),"" ) -> Desechable | J35: {=IF(ISNUMBER(A35),IFERROR(_xlfn._xlws.FILTER(Equipar!A:A,(Equipar!B:B=1)*(Equipar!AC:AC=A35)),""),"")}
A36: 36 | B36: Épico | C36: Ataque veloz | D36: Ataque rápido | E36: Ataque rápido | F36: Percepción | G36: Saque | H36: Recepción | I36: =IF(ISNUMBER(A36), IF(COUNTIFS(Equipar!B:B,1,Equipar!AC:AC,A36),"Equipada", IF( OR(COUNTIFS(Equipar!B:B,1,Equipar!C:C,A36) +COUNTIFS(Equipar!B:B,1,Equipar!D:D,A36) +COUNTIFS(Equipar!B:B,1,Equipar!E:E,A36) +COUNTIFS(Equipar!B:B,1,Equipar!F:F,A36) >0,COUNTIF('Set recomendado'!B:B,C36)=0), "Bloqueada", "Desechable")),"" ) -> Equipada | J36: {=IF(ISNUMBER(A36),IFERROR(_xlfn._xlws.FILTER(Equipar!A:A,(Equipar!B:B=1)*(Equipar!AC:AC=A36)),""),"")} -> Osamu
A37: 37 | B37: Épico | C37: Opt. de percepción | D37: Ataque rápido | E37: Recuperación | F37: Ataque rápido | G37: Ataque poderoso | I37: =IF(ISNUMBER(A37), IF(COUNTIFS(Equipar!B:B,1,Equipar!AC:AC,A37),"Equipada", IF( OR(COUNTIFS(Equipar!B:B,1,Equipar!C:C,A37) +COUNTIFS(Equipar!B:B,1,Equipar!D:D,A37) +COUNTIFS(Equipar!B:B,1,Equipar!E:E,A37) +COUNTIFS(Equipar!B:B,1,Equipar!F:F,A37) >0,COUNTIF('Set recomendado'!B:B,C37)=0), "Bloqueada", "Desechable")),"" ) -> Bloqueada | J37: {=IF(ISNUMBER(A37),IFERROR(_xlfn._xlws.FILTER(Equipar!A:A,(Equipar!B:B=1)*(Equipar!AC:AC=A37)),""),"")}
A38: 38 | B38: Épico | C38: Opt. de percepción | D38: Ataque rápido | E38: Colocación | F38: Recuperación | I38: =IF(ISNUMBER(A38), IF(COUNTIFS(Equipar!B:B,1,Equipar!AC:AC,A38),"Equipada", IF( OR(COUNTIFS(Equipar!B:B,1,Equipar!C:C,A38) +COUNTIFS(Equipar!B:B,1,Equipar!D:D,A38) +COUNTIFS(Equipar!B:B,1,Equipar!E:E,A38) +COUNTIFS(Equipar!B:B,1,Equipar!F:F,A38) >0,COUNTIF('Set recomendado'!B:B,C38)=0), "Bloqueada", "Desechable")),"" ) -> Bloqueada | J38: {=IF(ISNUMBER(A38),IFERROR(_xlfn._xlws.FILTER(Equipar!A:A,(Equipar!B:B=1)*(Equipar!AC:AC=A38)),""),"")}
A39: 39 | B39: Épico | C39: Opt. de percepción | D39: Ataque rápido | E39: Recuperación | F39: Ataque rápido | I39: =IF(ISNUMBER(A39), IF(COUNTIFS(Equipar!B:B,1,Equipar!AC:AC,A39),"Equipada", IF( OR(COUNTIFS(Equipar!B:B,1,Equipar!C:C,A39) +COUNTIFS(Equipar!B:B,1,Equipar!D:D,A39) +COUNTIFS(Equipar!B:B,1,Equipar!E:E,A39) +COUNTIFS(Equipar!B:B,1,Equipar!F:F,A39) >0,COUNTIF('Set recomendado'!B:B,C39)=0), "Bloqueada", "Desechable")),"" ) -> Bloqueada | J39: {=IF(ISNUMBER(A39),IFERROR(_xlfn._xlws.FILTER(Equipar!A:A,(Equipar!B:B=1)*(Equipar!AC:AC=A39)),""),"")}
A40: 40 | B40: Épico | C40: Finta de colocador | D40: Colocación | E40: Ataque poderoso | F40: Bloqueo | I40: =IF(ISNUMBER(A40), IF(COUNTIFS(Equipar!B:B,1,Equipar!AC:AC,A40),"Equipada", IF( OR(COUNTIFS(Equipar!B:B,1,Equipar!C:C,A40) +COUNTIFS(Equipar!B:B,1,Equipar!D:D,A40) +COUNTIFS(Equipar!B:B,1,Equipar!E:E,A40) +COUNTIFS(Equipar!B:B,1,Equipar!F:F,A40) >0,COUNTIF('Set recomendado'!B:B,C40)=0), "Bloqueada", "Desechable")),"" ) -> Desechable | J40: {=IF(ISNUMBER(A40),IFERROR(_xlfn._xlws.FILTER(Equipar!A:A,(Equipar!B:B=1)*(Equipar!AC:AC=A40)),""),"")}
...

Sheet Inventario2
A1: ID | B1: Calidad | C1: Tipo | D1: Main Stat | E1: Substat1 | F1: Substat2 | G1: Substat3 | H1: Substat4 | I1: Estado Act | J1: Jugador
A2: 3 | B2: Legendario | C2: Movimiento de bloqueo | D2: Saque | E2: Saque | F2: Ataque poderoso | G2: Recepción | H2: Recuperación | I2: =IF(ISNUMBER(A2), IF(COUNTIFS(Equipar!B:B,2,Equipar!AC:AC,A2),"Equipada", IF( OR(COUNTIFS(Equipar!B:B,2,Equipar!C:C,A2) +COUNTIFS(Equipar!B:B,2,Equipar!D:D,A2) +COUNTIFS(Equipar!B:B,2,Equipar!E:E,A2) +COUNTIFS(Equipar!B:B,2,Equipar!F:F,A2) >0,COUNTIF('Set recomendado'!B:B,C2)=0), "Bloqueada", "Desechable")),"" ) -> Desechable | J2: {=IF(ISNUMBER(A2),IFERROR(_xlfn._xlws.FILTER(Equipar!A:A,(Equipar!B:B=2)*(Equipar!AC:AC=A2)),""),"")}
A3: 4 | B3: Legendario | C3: Recepción de asistencia | D3: Saque | E3: Bloqueo | F3: Saque | G3: Ataque poderoso | H3: Colocación | I3: =IF(ISNUMBER(A3), IF(COUNTIFS(Equipar!B:B,2,Equipar!AC:AC,A3),"Equipada", IF( OR(COUNTIFS(Equipar!B:B,2,Equipar!C:C,A3) +COUNTIFS(Equipar!B:B,2,Equipar!D:D,A3) +COUNTIFS(Equipar!B:B,2,Equipar!E:E,A3) +COUNTIFS(Equipar!B:B,2,Equipar!F:F,A3) >0,COUNTIF('Set recomendado'!B:B,C3)=0), "Bloqueada", "Desechable")),"" ) -> Desechable | J3: {=IF(ISNUMBER(A3),IFERROR(_xlfn._xlws.FILTER(Equipar!A:A,(Equipar!B:B=2)*(Equipar!AC:AC=A3)),""),"")}
A4: 5 | B4: Legendario | C4: Saque preciso | D4: Colocación | E4: Recepción | F4: Saque | G4: Ataque poderoso | H4: Ataque rápido | I4: =IF(ISNUMBER(A4), IF(COUNTIFS(Equipar!B:B,2,Equipar!AC:AC,A4),"Equipada", IF( OR(COUNTIFS(Equipar!B:B,2,Equipar!C:C,A4) +COUNTIFS(Equipar!B:B,2,Equipar!D:D,A4) +COUNTIFS(Equipar!B:B,2,Equipar!E:E,A4) +COUNTIFS(Equipar!B:B,2,Equipar!F:F,A4) >0,COUNTIF('Set recomendado'!B:B,C4)=0), "Bloqueada", "Desechable")),"" ) -> Bloqueada | J4: {=IF(ISNUMBER(A4),IFERROR(_xlfn._xlws.FILTER(Equipar!A:A,(Equipar!B:B=2)*(Equipar!AC:AC=A4)),""),"")}
A5: 8 | B5: Legendario | C5: Incremento de poder | D5: Percepción | E5: Ataque rápido | F5: Recepción | G5: Espíritu | H5: Colocación | I5: =IF(ISNUMBER(A5), IF(COUNTIFS(Equipar!B:B,2,Equipar!AC:AC,A5),"Equipada", IF( OR(COUNTIFS(Equipar!B:B,2,Equipar!C:C,A5) +COUNTIFS(Equipar!B:B,2,Equipar!D:D,A5) +COUNTIFS(Equipar!B:B,2,Equipar!E:E,A5) +COUNTIFS(Equipar!B:B,2,Equipar!F:F,A5) >0,COUNTIF('Set recomendado'!B:B,C5)=0), "Bloqueada", "Desechable")),"" ) -> Desechable | J5: {=IF(ISNUMBER(A5),IFERROR(_xlfn._xlws.FILTER(Equipar!A:A,(Equipar!B:B=2)*(Equipar!AC:AC=A5)),""),"")}
A6: 10 | B6: Legendario | C6: Ataque veloz | D6: Ataque rápido | E6: Ataque poderoso | F6: Recepción | G6: Técnica ofensiva | H6: Bloqueo | I6: =IF(ISNUMBER(A6), IF(COUNTIFS(Equipar!B:B,2,Equipar!AC:AC,A6),"Equipada", IF( OR(COUNTIFS(Equipar!B:B,2,Equipar!C:C,A6) +COUNTIFS(Equipar!B:B,2,Equipar!D:D,A6) +COUNTIFS(Equipar!B:B,2,Equipar!E:E,A6) +COUNTIFS(Equipar!B:B,2,Equipar!F:F,A6) >0,COUNTIF('Set recomendado'!B:B,C6)=0), "Bloqueada", "Desechable")),"" ) -> Equipada | J6: {=IF(ISNUMBER(A6),IFERROR(_xlfn._xlws.FILTER(Equipar!A:A,(Equipar!B:B=2)*(Equipar!AC:AC=A6)),""),"")} -> Suna
A7: 11 | B7: Legendario | C7: Ataque veloz | D7: Saque | E7: Ataque rápido | F7: Recepción | G7: Recuperación | H7: Ataque poderoso | I7: =IF(ISNUMBER(A7), IF(COUNTIFS(Equipar!B:B,2,Equipar!AC:AC,A7),"Equipada", IF( OR(COUNTIFS(Equipar!B:B,2,Equipar!C:C,A7) +COUNTIFS(Equipar!B:B,2,Equipar!D:D,A7) +COUNTIFS(Equipar!B:B,2,Equipar!E:E,A7) +COUNTIFS(Equipar!B:B,2,Equipar!F:F,A7) >0,COUNTIF('Set recomendado'!B:B,C7)=0), "Bloqueada", "Desechable")),"" ) -> Desechable | J7: {=IF(ISNUMBER(A7),IFERROR(_xlfn._xlws.FILTER(Equipar!A:A,(Equipar!B:B=2)*(Equipar!AC:AC=A7)),""),"")}
A8: 14 | B8: Legendario | C8: Ataque veloz | D8: Fuerza | E8: Técnica defensiva | F8: Ataque rápido | G8: Ataque rápido | H8: Colocación | I8: =IF(ISNUMBER(A8), IF(COUNTIFS(Equipar!B:B,2,Equipar!AC:AC,A8),"Equipada", IF( OR(COUNTIFS(Equipar!B:B,2,Equipar!C:C,A8) +COUNTIFS(Equipar!B:B,2,Equipar!D:D,A8) +COUNTIFS(Equipar!B:B,2,Equipar!E:E,A8) +COUNTIFS(Equipar!B:B,2,Equipar!F:F,A8) >0,COUNTIF('Set recomendado'!B:B,C8)=0), "Bloqueada", "Desechable")),"" ) -> Equipada | J8: {=IF(ISNUMBER(A8),IFERROR(_xlfn._xlws.FILTER(Equipar!A:A,(Equipar!B:B=2)*(Equipar!AC:AC=A8)),""),"")} -> Hinata
A9: 15 | B9: Legendario | C9: Sentido agudo | D9: Saque | E9: Reflejos | F9: Bloqueo | G9: Recuperación | H9: Saque | I9: =IF(ISNUMBER(A9), IF(COUNTIFS(Equipar!B:B,2,Equipar!AC:AC,A9),"Equipada", IF( OR(COUNTIFS(Equipar!B:B,2,Equipar!C:C,A9) +COUNTIFS(Equipar!B:B,2,Equipar!D:D,A9) +COUNTIFS(Equipar!B:B,2,Equipar!E:E,A9) +COUNTIFS(Equipar!B:B,2,Equipar!F:F,A9) >0,COUNTIF('Set recomendado'!B:B,C9)=0), "Bloqueada", "Desechable")),"" ) -> Desechable | J9: {=IF(ISNUMBER(A9),IFERROR(_xlfn._xlws.FILTER(Equipar!A:A,(Equipar!B:B=2)*(Equipar!AC:AC=A9)),""),"")}
A10: 16 | B10: Legendario | C10: Sentido agudo | D10: Ataque rápido | E10: Recuperación | F10: Colocación | G10: Ataque rápido | I10: =IF(ISNUMBER(A10), IF(COUNTIFS(Equipar!B:B,2,Equipar!AC:AC,A10),"Equipada", IF( OR(COUNTIFS(Equipar!B:B,2,Equipar!C:C,A10) +COUNTIFS(Equipar!B:B,2,Equipar!D:D,A10) +COUNTIFS(Equipar!B:B,2,Equipar!E:E,A10) +COUNTIFS(Equipar!B:B,2,Equipar!F:F,A10) >0,COUNTIF('Set recomendado'!B:B,C10)=0), "Bloqueada", "Desechable")),"" ) -> Equipada | J10: {=IF(ISNUMBER(A10),IFERROR(_xlfn._xlws.FILTER(Equipar!A:A,(Equipar!B:B=2)*(Equipar!AC:AC=A10)),""),"")} -> Osamu
A11: 17 | B11: Legendario | C11: Sentido agudo | D11: Ataque rápido | E11: Espíritu | F11: Recepción | G11: Saque | I11: =IF(ISNUMBER(A11), IF(COUNTIFS(Equipar!B:B,2,Equipar!AC:AC,A11),"Equipada", IF( OR(COUNTIFS(Equipar!B:B,2,Equipar!C:C,A11) +COUNTIFS(Equipar!B:B,2,Equipar!D:D,A11) +COUNTIFS(Equipar!B:B,2,Equipar!E:E,A11) +COUNTIFS(Equipar!B:B,2,Equipar!F:F,A11) >0,COUNTIF('Set recomendado'!B:B,C11)=0), "Bloqueada", "Desechable")),"" ) -> Desechable | J11: {=IF(ISNUMBER(A11),IFERROR(_xlfn._xlws.FILTER(Equipar!A:A,(Equipar!B:B=2)*(Equipar!AC:AC=A11)),""),"")}
A12: 18 | B12: Legendario | C12: Sentido agudo | D12: Saque | E12: Recepción | F12: Colocación | G12: Recepción | I12: =IF(ISNUMBER(A12), IF(COUNTIFS(Equipar!B:B,2,Equipar!AC:AC,A12),"Equipada", IF( OR(COUNTIFS(Equipar!B:B,2,Equipar!C:C,A12) +COUNTIFS(Equipar!B:B,2,Equipar!D:D,A12) +COUNTIFS(Equipar!B:B,2,Equipar!E:E,A12) +COUNTIFS(Equipar!B:B,2,Equipar!F:F,A12) >0,COUNTIF('Set recomendado'!B:B,C12)=0), "Bloqueada", "Desechable")),"" ) -> Desechable | J12: {=IF(ISNUMBER(A12),IFERROR(_xlfn._xlws.FILTER(Equipar!A:A,(Equipar!B:B=2)*(Equipar!AC:AC=A12)),""),"")}
A13: 19 | B13: Legendario | C13: Sentido agudo | D13: Ataque rápido | E13: Colocación | F13: Técnica defensiva | G13: Ataque poderoso | H13: Colocación | I13: =IF(ISNUMBER(A13), IF(COUNTIFS(Equipar!B:B,2,Equipar!AC:AC,A13),"Equipada", IF( OR(COUNTIFS(Equipar!B:B,2,Equipar!C:C,A13) +COUNTIFS(Equipar!B:B,2,Equipar!D:D,A13) +COUNTIFS(Equipar!B:B,2,Equipar!E:E,A13) +COUNTIFS(Equipar!B:B,2,Equipar!F:F,A13) >0,COUNTIF('Set recomendado'!B:B,C13)=0), "Bloqueada", "Desechable")),"" ) -> Desechable | J13: {=IF(ISNUMBER(A13),IFERROR(_xlfn._xlws.FILTER(Equipar!A:A,(Equipar!B:B=2)*(Equipar!AC:AC=A13)),""),"")}
A14: 21 | B14: Legendario | C14: Bloque preciso | D14: Colocación | E14: Recuperación | F14: Bloqueo | G14: Colocación | I14: =IF(ISNUMBER(A14), IF(COUNTIFS(Equipar!B:B,2,Equipar!AC:AC,A14),"Equipada", IF( OR(COUNTIFS(Equipar!B:B,2,Equipar!C:C,A14) +COUNTIFS(Equipar!B:B,2,Equipar!D:D,A14) +COUNTIFS(Equipar!B:B,2,Equipar!E:E,A14) +COUNTIFS(Equipar!B:B,2,Equipar!F:F,A14) >0,COUNTIF('Set recomendado'!B:B,C14)=0), "Bloqueada", "Desechable")),"" ) -> Desechable | J14: {=IF(ISNUMBER(A14),IFERROR(_xlfn._xlws.FILTER(Equipar!A:A,(Equipar!B:B=2)*(Equipar!AC:AC=A14)),""),"")}
A15: 22 | B15: Legendario | C15: Recepción de asistencia | D15: Ataque rápido | E15: Saque | F15: Reflejos | G15: Colocación | I15: =IF(ISNUMBER(A15), IF(COUNTIFS(Equipar!B:B,2,Equipar!AC:AC,A15),"Equipada", IF( OR(COUNTIFS(Equipar!B:B,2,Equipar!C:C,A15) +COUNTIFS(Equipar!B:B,2,Equipar!D:D,A15) +COUNTIFS(Equipar!B:B,2,Equipar!E:E,A15) +COUNTIFS(Equipar!B:B,2,Equipar!F:F,A15) >0,COUNTIF('Set recomendado'!B:B,C15)=0), "Bloqueada", "Desechable")),"" ) -> Desechable | J15: {=IF(ISNUMBER(A15),IFERROR(_xlfn._xlws.FILTER(Equipar!A:A,(Equipar!B:B=2)*(Equipar!AC:AC=A15)),""),"")}
A16: 23 | B16: Legendario | C16: Recepción de asistencia | D16: Ataque poderoso | E16: Colocación | F16: Bloqueo | G16: Ataque rápido | I16: =IF(ISNUMBER(A16), IF(COUNTIFS(Equipar!B:B,2,Equipar!AC:AC,A16),"Equipada", IF( OR(COUNTIFS(Equipar!B:B,2,Equipar!C:C,A16) +COUNTIFS(Equipar!B:B,2,Equipar!D:D,A16) +COUNTIFS(Equipar!B:B,2,Equipar!E:E,A16) +COUNTIFS(Equipar!B:B,2,Equipar!F:F,A16) >0,COUNTIF('Set recomendado'!B:B,C16)=0), "Bloqueada", "Desechable")),"" ) -> Desechable | J16: {=IF(ISNUMBER(A16),IFERROR(_xlfn._xlws.FILTER(Equipar!A:A,(Equipar!B:B=2)*(Equipar!AC:AC=A16)),""),"")}
A17: 24 | B17: Legendario | C17: Recepción de asistencia | D17: Percepción | E17: Espíritu | F17: Colocación | G17: Colocación | I17: =IF(ISNUMBER(A17), IF(COUNTIFS(Equipar!B:B,2,Equipar!AC:AC,A17),"Equipada", IF( OR(COUNTIFS(Equipar!B:B,2,Equipar!C:C,A17) +COUNTIFS(Equipar!B:B,2,Equipar!D:D,A17) +COUNTIFS(Equipar!B:B,2,Equipar!E:E,A17) +COUNTIFS(Equipar!B:B,2,Equipar!F:F,A17) >0,COUNTIF('Set recomendado'!B:B,C17)=0), "Bloqueada", "Desechable")),"" ) -> Desechable | J17: {=IF(ISNUMBER(A17),IFERROR(_xlfn._xlws.FILTER(Equipar!A:A,(Equipar!B:B=2)*(Equipar!AC:AC=A17)),""),"")}
A18: 25 | B18: Legendario | C18: Recepción de asistencia | D18: Ataque rápido | E18: Ataque rápido | F18: Reflejos | G18: Colocación | H18: Ataque poderoso | I18: =IF(ISNUMBER(A18), IF(COUNTIFS(Equipar!B:B,2,Equipar!AC:AC,A18),"Equipada", IF( OR(COUNTIFS(Equipar!B:B,2,Equipar!C:C,A18) +COUNTIFS(Equipar!B:B,2,Equipar!D:D,A18) +COUNTIFS(Equipar!B:B,2,Equipar!E:E,A18) +COUNTIFS(Equipar!B:B,2,Equipar!F:F,A18) >0,COUNTIF('Set recomendado'!B:B,C18)=0), "Bloqueada", "Desechable")),"" ) -> Desechable | J18: {=IF(ISNUMBER(A18),IFERROR(_xlfn._xlws.FILTER(Equipar!A:A,(Equipar!B:B=2)*(Equipar!AC:AC=A18)),""),"")}
A19: 26 | B19: Legendario | C19: Recepción suprema | D19: Saque | E19: Saque | F19: Ataque poderoso | G19: Bloqueo | I19: =IF(ISNUMBER(A19), IF(COUNTIFS(Equipar!B:B,2,Equipar!AC:AC,A19),"Equipada", IF( OR(COUNTIFS(Equipar!B:B,2,Equipar!C:C,A19) +COUNTIFS(Equipar!B:B,2,Equipar!D:D,A19) +COUNTIFS(Equipar!B:B,2,Equipar!E:E,A19) +COUNTIFS(Equipar!B:B,2,Equipar!F:F,A19) >0,COUNTIF('Set recomendado'!B:B,C19)=0), "Bloqueada", "Desechable")),"" ) -> Desechable | J19: {=IF(ISNUMBER(A19),IFERROR(_xlfn._xlws.FILTER(Equipar!A:A,(Equipar!B:B=2)*(Equipar!AC:AC=A19)),""),"")}
A20: 27 | B20: Legendario | C20: Opt. de percepción | D20: Percepción | E20: Recuperación | F20: Recuperación | I20: =IF(ISNUMBER(A20), IF(COUNTIFS(Equipar!B:B,2,Equipar!AC:AC,A20),"Equipada", IF( OR(COUNTIFS(Equipar!B:B,2,Equipar!C:C,A20) +COUNTIFS(Equipar!B:B,2,Equipar!D:D,A20) +COUNTIFS(Equipar!B:B,2,Equipar!E:E,A20) +COUNTIFS(Equipar!B:B,2,Equipar!F:F,A20) >0,COUNTIF('Set recomendado'!B:B,C20)=0), "Bloqueada", "Desechable")),"" ) -> Bloqueada | J20: {=IF(ISNUMBER(A20),IFERROR(_xlfn._xlws.FILTER(Equipar!A:A,(Equipar!B:B=2)*(Equipar!AC:AC=A20)),""),"")}
A21: 28 | B21: Legendario | C21: Finta de colocador | D21: Ataque poderoso | E21: Saque | F21: Percepción | G21: Colocación | I21: =IF(ISNUMBER(A21), IF(COUNTIFS(Equipar!B:B,2,Equipar!AC:AC,A21),"Equipada", IF( OR(COUNTIFS(Equipar!B:B,2,Equipar!C:C,A21) +COUNTIFS(Equipar!B:B,2,Equipar!D:D,A21) +COUNTIFS(Equipar!B:B,2,Equipar!E:E,A21) +COUNTIFS(Equipar!B:B,2,Equipar!F:F,A21) >0,COUNTIF('Set recomendado'!B:B,C21)=0), "Bloqueada", "Desechable")),"" ) -> Bloqueada | J21: {=IF(ISNUMBER(A21),IFERROR(_xlfn._xlws.FILTER(Equipar!A:A,(Equipar!B:B=2)*(Equipar!AC:AC=A21)),""),"")}
A22: 29 | B22: Legendario | C22: Finta de colocador | D22: Ataque rápido | E22: Recepción | F22: Saque | G22: Técnica defensiva | H22: Ataque poderoso | I22: =IF(ISNUMBER(A22), IF(COUNTIFS(Equipar!B:B,2,Equipar!AC:AC,A22),"Equipada", IF( OR(COUNTIFS(Equipar!B:B,2,Equipar!C:C,A22) +COUNTIFS(Equipar!B:B,2,Equipar!D:D,A22) +COUNTIFS(Equipar!B:B,2,Equipar!E:E,A22) +COUNTIFS(Equipar!B:B,2,Equipar!F:F,A22) >0,COUNTIF('Set recomendado'!B:B,C22)=0), "Bloqueada", "Desechable")),"" ) -> Desechable | J22: {=IF(ISNUMBER(A22),IFERROR(_xlfn._xlws.FILTER(Equipar!A:A,(Equipar!B:B=2)*(Equipar!AC:AC=A22)),""),"")}
A23: 30 | B23: Épico | C23: Saque preciso | D23: Saque | E23: Saque | F23: Colocación | G23: Fuerza | H23: Bloqueo | I23: =IF(ISNUMBER(A23), IF(COUNTIFS(Equipar!B:B,2,Equipar!AC:AC,A23),"Equipada", IF( OR(COUNTIFS(Equipar!B:B,2,Equipar!C:C,A23) +COUNTIFS(Equipar!B:B,2,Equipar!D:D,A23) +COUNTIFS(Equipar!B:B,2,Equipar!E:E,A23) +COUNTIFS(Equipar!B:B,2,Equipar!F:F,A23) >0,COUNTIF('Set recomendado'!B:B,C23)=0), "Bloqueada", "Desechable")),"" ) -> Equipada | J23: {=IF(ISNUMBER(A23),IFERROR(_xlfn._xlws.FILTER(Equipar!A:A,(Equipar!B:B=2)*(Equipar!AC:AC=A23)),""),"")} -> Oikawa
A24: 31 | B24: Épico | C24: Pase preciso | D24: Colocación | E24: Colocación | F24: Colocación | G24: Técnica ofensiva | H24: Ataque rápido | I24: =IF(ISNUMBER(A24), IF(COUNTIFS(Equipar!B:B,2,Equipar!AC:AC,A24),"Equipada", IF( OR(COUNTIFS(Equipar!B:B,2,Equipar!C:C,A24) +COUNTIFS(Equipar!B:B,2,Equipar!D:D,A24) +COUNTIFS(Equipar!B:B,2,Equipar!E:E,A24) +COUNTIFS(Equipar!B:B,2,Equipar!F:F,A24) >0,COUNTIF('Set recomendado'!B:B,C24)=0), "Bloqueada", "Desechable")),"" ) -> Desechable | J24: {=IF(ISNUMBER(A24),IFERROR(_xlfn._xlws.FILTER(Equipar!A:A,(Equipar!B:B=2)*(Equipar!AC:AC=A24)),""),"")}
A25: 32 | B25: Épico | C25: Poder vibrante | D25: Ataque poderoso | E25: Ataque poderoso | F25: Saque | G25: Ataque poderoso | H25: Espíritu | I25: =IF(ISNUMBER(A25), IF(COUNTIFS(Equipar!B:B,2,Equipar!AC:AC,A25),"Equipada", IF( OR(COUNTIFS(Equipar!B:B,2,Equipar!C:C,A25) +COUNTIFS(Equipar!B:B,2,Equipar!D:D,A25) +COUNTIFS(Equipar!B:B,2,Equipar!E:E,A25) +COUNTIFS(Equipar!B:B,2,Equipar!F:F,A25) >0,COUNTIF('Set recomendado'!B:B,C25)=0), "Bloqueada", "Desechable")),"" ) -> Equipada | J25: {=IF(ISNUMBER(A25),IFERROR(_xlfn._xlws.FILTER(Equipar!A:A,(Equipar!B:B=2)*(Equipar!AC:AC=A25)),""),"")} -> Hoshiumi
A26: 33 | B26: Épico | C26: Poder vibrante | D26: Ataque poderoso | E26: Colocación | F26: Colocación | G26: Ataque poderoso | H26: Recepción | I26: =IF(ISNUMBER(A26), IF(COUNTIFS(Equipar!B:B,2,Equipar!AC:AC,A26),"Equipada", IF( OR(COUNTIFS(Equipar!B:B,2,Equipar!C:C,A26) +COUNTIFS(Equipar!B:B,2,Equipar!D:D,A26) +COUNTIFS(Equipar!B:B,2,Equipar!E:E,A26) +COUNTIFS(Equipar!B:B,2,Equipar!F:F,A26) >0,COUNTIF('Set recomendado'!B:B,C26)=0), "Bloqueada", "Desechable")),"" ) -> Equipada | J26: {=IF(ISNUMBER(A26),IFERROR(_xlfn._xlws.FILTER(Equipar!A:A,(Equipar!B:B=2)*(Equipar!AC:AC=A26)),""),"")} -> Tanaka
A27: 35 | B27: Épico | C27: Saque preciso | D27: Saque | E27: Ataque poderoso | F27: Colocación | I27: =IF(ISNUMBER(A27), IF(COUNTIFS(Equipar!B:B,2,Equipar!AC:AC,A27),"Equipada", IF( OR(COUNTIFS(Equipar!B:B,2,Equipar!C:C,A27) +COUNTIFS(Equipar!B:B,2,Equipar!D:D,A27) +COUNTIFS(Equipar!B:B,2,Equipar!E:E,A27) +COUNTIFS(Equipar!B:B,2,Equipar!F:F,A27) >0,COUNTIF('Set recomendado'!B:B,C27)=0), "Bloqueada", "Desechable")),"" ) -> Desechable | J27: {=IF(ISNUMBER(A27),IFERROR(_xlfn._xlws.FILTER(Equipar!A:A,(Equipar!B:B=2)*(Equipar!AC:AC=A27)),""),"")}
A28: 38 | B28: Épico | C28: Poder vibrante | D28: Ataque poderoso | E28: Técnica defensiva | F28: Recepción | I28: =IF(ISNUMBER(A28), IF(COUNTIFS(Equipar!B:B,2,Equipar!AC:AC,A28),"Equipada", IF( OR(COUNTIFS(Equipar!B:B,2,Equipar!C:C,A28) +COUNTIFS(Equipar!B:B,2,Equipar!D:D,A28) +COUNTIFS(Equipar!B:B,2,Equipar!E:E,A28) +COUNTIFS(Equipar!B:B,2,Equipar!F:F,A28) >0,COUNTIF('Set recomendado'!B:B,C28)=0), "Bloqueada", "Desechable")),"" ) -> Desechable | J28: {=IF(ISNUMBER(A28),IFERROR(_xlfn._xlws.FILTER(Equipar!A:A,(Equipar!B:B=2)*(Equipar!AC:AC=A28)),""),"")}
A29: 40 | B29: Épico | C29: Poder vibrante | D29: Percepción | E29: Saque | F29: Colocación | I29: =IF(ISNUMBER(A29), IF(COUNTIFS(Equipar!B:B,2,Equipar!AC:AC,A29),"Equipada", IF( OR(COUNTIFS(Equipar!B:B,2,Equipar!C:C,A29) +COUNTIFS(Equipar!B:B,2,Equipar!D:D,A29) +COUNTIFS(Equipar!B:B,2,Equipar!E:E,A29) +COUNTIFS(Equipar!B:B,2,Equipar!F:F,A29) >0,COUNTIF('Set recomendado'!B:B,C29)=0), "Bloqueada", "Desechable")),"" ) -> Desechable | J29: {=IF(ISNUMBER(A29),IFERROR(_xlfn._xlws.FILTER(Equipar!A:A,(Equipar!B:B=2)*(Equipar!AC:AC=A29)),""),"")}
A30: 41 | B30: Épico | C30: Poder vibrante | D30: Saque | E30: Fuerza | F30: Ataque poderoso | I30: =IF(ISNUMBER(A30), IF(COUNTIFS(Equipar!B:B,2,Equipar!AC:AC,A30),"Equipada", IF( OR(COUNTIFS(Equipar!B:B,2,Equipar!C:C,A30) +COUNTIFS(Equipar!B:B,2,Equipar!D:D,A30) +COUNTIFS(Equipar!B:B,2,Equipar!E:E,A30) +COUNTIFS(Equipar!B:B,2,Equipar!F:F,A30) >0,COUNTIF('Set recomendado'!B:B,C30)=0), "Bloqueada", "Desechable")),"" ) -> Equipada | J30: {=IF(ISNUMBER(A30),IFERROR(_xlfn._xlws.FILTER(Equipar!A:A,(Equipar!B:B=2)*(Equipar!AC:AC=A30)),""),"")} -> Kyotani
A31: 42 | B31: Épico | C31: Incremento de poder | D31: Percepción | E31: Reflejos | F31: Ataque poderoso | I31: =IF(ISNUMBER(A31), IF(COUNTIFS(Equipar!B:B,2,Equipar!AC:AC,A31),"Equipada", IF( OR(COUNTIFS(Equipar!B:B,2,Equipar!C:C,A31) +COUNTIFS(Equipar!B:B,2,Equipar!D:D,A31) +COUNTIFS(Equipar!B:B,2,Equipar!E:E,A31) +COUNTIFS(Equipar!B:B,2,Equipar!F:F,A31) >0,COUNTIF('Set recomendado'!B:B,C31)=0), "Bloqueada", "Desechable")),"" ) -> Desechable | J31: {=IF(ISNUMBER(A31),IFERROR(_xlfn._xlws.FILTER(Equipar!A:A,(Equipar!B:B=2)*(Equipar!AC:AC=A31)),""),"")}
A32: 43 | B32: Épico | C32: Incremento de poder | D32: Ataque poderoso | E32: Bloqueo | F32: Recepción | G32: Técnica ofensiva | I32: =IF(ISNUMBER(A32), IF(COUNTIFS(Equipar!B:B,2,Equipar!AC:AC,A32),"Equipada", IF( OR(COUNTIFS(Equipar!B:B,2,Equipar!C:C,A32) +COUNTIFS(Equipar!B:B,2,Equipar!D:D,A32) +COUNTIFS(Equipar!B:B,2,Equipar!E:E,A32) +COUNTIFS(Equipar!B:B,2,Equipar!F:F,A32) >0,COUNTIF('Set recomendado'!B:B,C32)=0), "Bloqueada", "Desechable")),"" ) -> Bloqueada | J32: {=IF(ISNUMBER(A32),IFERROR(_xlfn._xlws.FILTER(Equipar!A:A,(Equipar!B:B=2)*(Equipar!AC:AC=A32)),""),"")}
A33: 44 | B33: Épico | C33: Incremento de poder | D33: Percepción | E33: Ataque rápido | F33: Ataque poderoso | I33: =IF(ISNUMBER(A33), IF(COUNTIFS(Equipar!B:B,2,Equipar!AC:AC,A33),"Equipada", IF( OR(COUNTIFS(Equipar!B:B,2,Equipar!C:C,A33) +COUNTIFS(Equipar!B:B,2,Equipar!D:D,A33) +COUNTIFS(Equipar!B:B,2,Equipar!E:E,A33) +COUNTIFS(Equipar!B:B,2,Equipar!F:F,A33) >0,COUNTIF('Set recomendado'!B:B,C33)=0), "Bloqueada", "Desechable")),"" ) -> Desechable | J33: {=IF(ISNUMBER(A33),IFERROR(_xlfn._xlws.FILTER(Equipar!A:A,(Equipar!B:B=2)*(Equipar!AC:AC=A33)),""),"")}
A34: 45 | B34: Épico | C34: Incremento de poder | D34: Percepción | E34: Saque | F34: Ataque poderoso | I34: =IF(ISNUMBER(A34), IF(COUNTIFS(Equipar!B:B,2,Equipar!AC:AC,A34),"Equipada", IF( OR(COUNTIFS(Equipar!B:B,2,Equipar!C:C,A34) +COUNTIFS(Equipar!B:B,2,Equipar!D:D,A34) +COUNTIFS(Equipar!B:B,2,Equipar!E:E,A34) +COUNTIFS(Equipar!B:B,2,Equipar!F:F,A34) >0,COUNTIF('Set recomendado'!B:B,C34)=0), "Bloqueada", "Desechable")),"" ) -> Equipada | J34: {=IF(ISNUMBER(A34),IFERROR(_xlfn._xlws.FILTER(Equipar!A:A,(Equipar!B:B=2)*(Equipar!AC:AC=A34)),""),"")} -> Yamamoto
A35: 46 | B35: Épico | C35: Ataque veloz | D35: Saque | E35: Ataque rápido | F35: Ataque rápido | I35: =IF(ISNUMBER(A35), IF(COUNTIFS(Equipar!B:B,2,Equipar!AC:AC,A35),"Equipada", IF( OR(COUNTIFS(Equipar!B:B,2,Equipar!C:C,A35) +COUNTIFS(Equipar!B:B,2,Equipar!D:D,A35) +COUNTIFS(Equipar!B:B,2,Equipar!E:E,A35) +COUNTIFS(Equipar!B:B,2,Equipar!F:F,A35) >0,COUNTIF('Set recomendado'!B:B,C35)=0), "Bloqueada", "Desechable")),"" ) -> Bloqueada | J35: {=IF(ISNUMBER(A35),IFERROR(_xlfn._xlws.FILTER(Equipar!A:A,(Equipar!B:B=2)*(Equipar!AC:AC=A35)),""),"")}
A36: 47 | B36: Épico | C36: Ataque veloz | D36: Ataque rápido | E36: Ataque poderoso | F36: Recepción | I36: =IF(ISNUMBER(A36), IF(COUNTIFS(Equipar!B:B,2,Equipar!AC:AC,A36),"Equipada", IF( OR(COUNTIFS(Equipar!B:B,2,Equipar!C:C,A36) +COUNTIFS(Equipar!B:B,2,Equipar!D:D,A36) +COUNTIFS(Equipar!B:B,2,Equipar!E:E,A36) +COUNTIFS(Equipar!B:B,2,Equipar!F:F,A36) >0,COUNTIF('Set recomendado'!B:B,C36)=0), "Bloqueada", "Desechable")),"" ) -> Desechable | J36: {=IF(ISNUMBER(A36),IFERROR(_xlfn._xlws.FILTER(Equipar!A:A,(Equipar!B:B=2)*(Equipar!AC:AC=A36)),""),"")}
A37: 48 | B37: Épico | C37: Bloque preciso | D37: Saque | E37: Técnica defensiva | F37: Bloqueo | G37: Ataque poderoso | I37: =IF(ISNUMBER(A37), IF(COUNTIFS(Equipar!B:B,2,Equipar!AC:AC,A37),"Equipada", IF( OR(COUNTIFS(Equipar!B:B,2,Equipar!C:C,A37) +COUNTIFS(Equipar!B:B,2,Equipar!D:D,A37) +COUNTIFS(Equipar!B:B,2,Equipar!E:E,A37) +COUNTIFS(Equipar!B:B,2,Equipar!F:F,A37) >0,COUNTIF('Set recomendado'!B:B,C37)=0), "Bloqueada", "Desechable")),"" ) -> Bloqueada | J37: {=IF(ISNUMBER(A37),IFERROR(_xlfn._xlws.FILTER(Equipar!A:A,(Equipar!B:B=2)*(Equipar!AC:AC=A37)),""),"")}
A38: 50 | B38: Épico | C38: Movimiento de bloqueo | D38: Fuerza | E38: Saque | F38: Recuperación | G38: Bloqueo | I38: =IF(ISNUMBER(A38), IF(COUNTIFS(Equipar!B:B,2,Equipar!AC:AC,A38),"Equipada", IF( OR(COUNTIFS(Equipar!B:B,2,Equipar!C:C,A38) +COUNTIFS(Equipar!B:B,2,Equipar!D:D,A38) +COUNTIFS(Equipar!B:B,2,Equipar!E:E,A38) +COUNTIFS(Equipar!B:B,2,Equipar!F:F,A38) >0,COUNTIF('Set recomendado'!B:B,C38)=0), "Bloqueada", "Desechable")),"" ) -> Desechable | J38: {=IF(ISNUMBER(A38),IFERROR(_xlfn._xlws.FILTER(Equipar!A:A,(Equipar!B:B=2)*(Equipar!AC:AC=A38)),""),"")}
A39: 51 | B39: Épico | C39: Recepción de asistencia | D39: Ataque poderoso | E39: Recepción | F39: Colocación | G39: Ataque poderoso | I39: =IF(ISNUMBER(A39), IF(COUNTIFS(Equipar!B:B,2,Equipar!AC:AC,A39),"Equipada", IF( OR(COUNTIFS(Equipar!B:B,2,Equipar!C:C,A39) +COUNTIFS(Equipar!B:B,2,Equipar!D:D,A39) +COUNTIFS(Equipar!B:B,2,Equipar!E:E,A39) +COUNTIFS(Equipar!B:B,2,Equipar!F:F,A39) >0,COUNTIF('Set recomendado'!B:B,C39)=0), "Bloqueada", "Desechable")),"" ) -> Equipada | J39: {=IF(ISNUMBER(A39),IFERROR(_xlfn._xlws.FILTER(Equipar!A:A,(Equipar!B:B=2)*(Equipar!AC:AC=A39)),""),"")} -> Sakusa
A40: 52 | B40: Épico | C40: Recepción de asistencia | D40: Ataque rápido | E40: Recuperación | F40: Recepción | G40: Técnica defensiva | I40: =IF(ISNUMBER(A40), IF(COUNTIFS(Equipar!B:B,2,Equipar!AC:AC,A40),"Equipada", IF( OR(COUNTIFS(Equipar!B:B,2,Equipar!C:C,A40) +COUNTIFS(Equipar!B:B,2,Equipar!D:D,A40) +COUNTIFS(Equipar!B:B,2,Equipar!E:E,A40) +COUNTIFS(Equipar!B:B,2,Equipar!F:F,A40) >0,COUNTIF('Set recomendado'!B:B,C40)=0), "Bloqueada", "Desechable")),"" ) -> Equipada | J40: {=IF(ISNUMBER(A40),IFERROR(_xlfn._xlws.FILTER(Equipar!A:A,(Equipar!B:B=2)*(Equipar!AC:AC=A40)),""),"")} -> Kita
...

Sheet Inventario3
A1: ID | B1: Calidad | C1: Tipo | D1: Main Stat | E1: Substat1 | F1: Substat2 | G1: Substat3 | H1: Substat4 | I1: Estado Act | J1: Jugador
A2: 2 | B2: Legendario | C2: Incremento de poder | D2: Saque | E2: Percepción | F2: Saque | G2: Ataque poderoso | H2: Bloqueo | I2: =IF(ISNUMBER(A2), IF(COUNTIFS(Equipar!B:B,3,Equipar!AC:AC,A2),"Equipada", IF( OR(COUNTIFS(Equipar!B:B,3,Equipar!C:C,A2) +COUNTIFS(Equipar!B:B,3,Equipar!D:D,A2) +COUNTIFS(Equipar!B:B,3,Equipar!E:E,A2) +COUNTIFS(Equipar!B:B,3,Equipar!F:F,A2) >0,COUNTIF('Set recomendado'!B:B,C2)=0), "Bloqueada", "Desechable")),"" ) -> Equipada | J2: {=IF(ISNUMBER(A2),IFERROR(_xlfn._xlws.FILTER(Equipar!A:A,(Equipar!B:B=3)*(Equipar!AC:AC=A2)),""),"")} -> Hoshiumi
A3: 3 | B3: Legendario | C3: Poder vibrante | D3: Saque | E3: Técnica defensiva | F3: Colocación | G3: Recepción | H3: Ataque poderoso | I3: =IF(ISNUMBER(A3), IF(COUNTIFS(Equipar!B:B,3,Equipar!AC:AC,A3),"Equipada", IF( OR(COUNTIFS(Equipar!B:B,3,Equipar!C:C,A3) +COUNTIFS(Equipar!B:B,3,Equipar!D:D,A3) +COUNTIFS(Equipar!B:B,3,Equipar!E:E,A3) +COUNTIFS(Equipar!B:B,3,Equipar!F:F,A3) >0,COUNTIF('Set recomendado'!B:B,C3)=0), "Bloqueada", "Desechable")),"" ) -> Equipada | J3: {=IF(ISNUMBER(A3),IFERROR(_xlfn._xlws.FILTER(Equipar!A:A,(Equipar!B:B=3)*(Equipar!AC:AC=A3)),""),"")} -> Sakusa
A4: 4 | B4: Legendario | C4: Poder vibrante | D4: Saque | E4: Técnica ofensiva | F4: Colocación | G4: Saque | H4: Ataque rápido | I4: =IF(ISNUMBER(A4), IF(COUNTIFS(Equipar!B:B,3,Equipar!AC:AC,A4),"Equipada", IF( OR(COUNTIFS(Equipar!B:B,3,Equipar!C:C,A4) +COUNTIFS(Equipar!B:B,3,Equipar!D:D,A4) +COUNTIFS(Equipar!B:B,3,Equipar!E:E,A4) +COUNTIFS(Equipar!B:B,3,Equipar!F:F,A4) >0,COUNTIF('Set recomendado'!B:B,C4)=0), "Bloqueada", "Desechable")),"" ) -> Equipada | J4: {=IF(ISNUMBER(A4),IFERROR(_xlfn._xlws.FILTER(Equipar!A:A,(Equipar!B:B=3)*(Equipar!AC:AC=A4)),""),"")} -> Kyotani
A5: 6 | B5: Legendario | C5: Incremento de poder | D5: Saque | E5: Recepción | F5: Ataque poderoso | G5: Recepción | H5: Técnica defensiva | I5: =IF(ISNUMBER(A5), IF(COUNTIFS(Equipar!B:B,3,Equipar!AC:AC,A5),"Equipada", IF( OR(COUNTIFS(Equipar!B:B,3,Equipar!C:C,A5) +COUNTIFS(Equipar!B:B,3,Equipar!D:D,A5) +COUNTIFS(Equipar!B:B,3,Equipar!E:E,A5) +COUNTIFS(Equipar!B:B,3,Equipar!F:F,A5) >0,COUNTIF('Set recomendado'!B:B,C5)=0), "Bloqueada", "Desechable")),"" ) -> Equipada | J5: {=IF(ISNUMBER(A5),IFERROR(_xlfn._xlws.FILTER(Equipar!A:A,(Equipar!B:B=3)*(Equipar!AC:AC=A5)),""),"")} -> Tanaka
A6: 8 | B6: Épico | C6: Poder vibrante | D6: Saque | E6: Saque | F6: Fuerza | G6: Bloqueo | H6: Recepción | I6: =IF(ISNUMBER(A6), IF(COUNTIFS(Equipar!B:B,3,Equipar!AC:AC,A6),"Equipada", IF( OR(COUNTIFS(Equipar!B:B,3,Equipar!C:C,A6) +COUNTIFS(Equipar!B:B,3,Equipar!D:D,A6) +COUNTIFS(Equipar!B:B,3,Equipar!E:E,A6) +COUNTIFS(Equipar!B:B,3,Equipar!F:F,A6) >0,COUNTIF('Set recomendado'!B:B,C6)=0), "Bloqueada", "Desechable")),"" ) -> Bloqueada | J6: {=IF(ISNUMBER(A6),IFERROR(_xlfn._xlws.FILTER(Equipar!A:A,(Equipar!B:B=3)*(Equipar!AC:AC=A6)),""),"")}
A7: 9 | B7: Épico | C7: Incremento de poder | D7: Saque | E7: Técnica ofensiva | F7: Ataque poderoso | G7: Fuerza | H7: Reflejos | I7: =IF(ISNUMBER(A7), IF(COUNTIFS(Equipar!B:B,3,Equipar!AC:AC,A7),"Equipada", IF( OR(COUNTIFS(Equipar!B:B,3,Equipar!C:C,A7) +COUNTIFS(Equipar!B:B,3,Equipar!D:D,A7) +COUNTIFS(Equipar!B:B,3,Equipar!E:E,A7) +COUNTIFS(Equipar!B:B,3,Equipar!F:F,A7) >0,COUNTIF('Set recomendado'!B:B,C7)=0), "Bloqueada", "Desechable")),"" ) -> Equipada | J7: {=IF(ISNUMBER(A7),IFERROR(_xlfn._xlws.FILTER(Equipar!A:A,(Equipar!B:B=3)*(Equipar!AC:AC=A7)),""),"")} -> Yamamoto
A8: 18 | B8: Épico | C8: Poder vibrante | D8: Saque | E8: Fuerza | F8: Ataque rápido | G8: Ataque poderoso | I8: =IF(ISNUMBER(A8), IF(COUNTIFS(Equipar!B:B,3,Equipar!AC:AC,A8),"Equipada", IF( OR(COUNTIFS(Equipar!B:B,3,Equipar!C:C,A8) +COUNTIFS(Equipar!B:B,3,Equipar!D:D,A8) +COUNTIFS(Equipar!B:B,3,Equipar!E:E,A8) +COUNTIFS(Equipar!B:B,3,Equipar!F:F,A8) >0,COUNTIF('Set recomendado'!B:B,C8)=0), "Bloqueada", "Desechable")),"" ) -> Desechable | J8: {=IF(ISNUMBER(A8),IFERROR(_xlfn._xlws.FILTER(Equipar!A:A,(Equipar!B:B=3)*(Equipar!AC:AC=A8)),""),"")}
A9: 37 | B9: Legendario | C9: Saque preciso | D9: Saque | E9: Colocación | F9: Reflejos | G9: Saque | H9: Colocación | I9: =IF(ISNUMBER(A9), IF(COUNTIFS(Equipar!B:B,3,Equipar!AC:AC,A9),"Equipada", IF( OR(COUNTIFS(Equipar!B:B,3,Equipar!C:C,A9) +COUNTIFS(Equipar!B:B,3,Equipar!D:D,A9) +COUNTIFS(Equipar!B:B,3,Equipar!E:E,A9) +COUNTIFS(Equipar!B:B,3,Equipar!F:F,A9) >0,COUNTIF('Set recomendado'!B:B,C9)=0), "Bloqueada", "Desechable")),"" ) -> Equipada | J9: {=IF(ISNUMBER(A9),IFERROR(_xlfn._xlws.FILTER(Equipar!A:A,(Equipar!B:B=3)*(Equipar!AC:AC=A9)),""),"")} -> Oikawa
A10: 38 | B10: Legendario | C10: Pase preciso | D10: Saque | E10: Ataque poderoso | F10: Saque | G10: Recepción | I10: =IF(ISNUMBER(A10), IF(COUNTIFS(Equipar!B:B,3,Equipar!AC:AC,A10),"Equipada", IF( OR(COUNTIFS(Equipar!B:B,3,Equipar!C:C,A10) +COUNTIFS(Equipar!B:B,3,Equipar!D:D,A10) +COUNTIFS(Equipar!B:B,3,Equipar!E:E,A10) +COUNTIFS(Equipar!B:B,3,Equipar!F:F,A10) >0,COUNTIF('Set recomendado'!B:B,C10)=0), "Bloqueada", "Desechable")),"" ) -> Desechable | J10: {=IF(ISNUMBER(A10),IFERROR(_xlfn._xlws.FILTER(Equipar!A:A,(Equipar!B:B=3)*(Equipar!AC:AC=A10)),""),"")}
A11: 47 | B11: Épico | C11: Saque preciso | D11: Saque | E11: Saque | F11: Recuperación | G11: Colocación | I11: =IF(ISNUMBER(A11), IF(COUNTIFS(Equipar!B:B,3,Equipar!AC:AC,A11),"Equipada", IF( OR(COUNTIFS(Equipar!B:B,3,Equipar!C:C,A11) +COUNTIFS(Equipar!B:B,3,Equipar!D:D,A11) +COUNTIFS(Equipar!B:B,3,Equipar!E:E,A11) +COUNTIFS(Equipar!B:B,3,Equipar!F:F,A11) >0,COUNTIF('Set recomendado'!B:B,C11)=0), "Bloqueada", "Desechable")),"" ) -> Desechable | J11: {=IF(ISNUMBER(A11),IFERROR(_xlfn._xlws.FILTER(Equipar!A:A,(Equipar!B:B=3)*(Equipar!AC:AC=A11)),""),"")}
A12: 67 | B12: Épico | C12: Pase preciso | D12: Saque | E12: Saque | F12: Colocación | G12: Recuperación | I12: =IF(ISNUMBER(A12), IF(COUNTIFS(Equipar!B:B,3,Equipar!AC:AC,A12),"Equipada", IF( OR(COUNTIFS(Equipar!B:B,3,Equipar!C:C,A12) +COUNTIFS(Equipar!B:B,3,Equipar!D:D,A12) +COUNTIFS(Equipar!B:B,3,Equipar!E:E,A12) +COUNTIFS(Equipar!B:B,3,Equipar!F:F,A12) >0,COUNTIF('Set recomendado'!B:B,C12)=0), "Bloqueada", "Desechable")),"" ) -> Bloqueada | J12: {=IF(ISNUMBER(A12),IFERROR(_xlfn._xlws.FILTER(Equipar!A:A,(Equipar!B:B=3)*(Equipar!AC:AC=A12)),""),"")}
A13: 73 | B13: Legendario | C13: Ataque veloz | D13: Saque | E13: Ataque rápido | F13: Ataque poderoso | G13: Colocación | I13: =IF(ISNUMBER(A13), IF(COUNTIFS(Equipar!B:B,3,Equipar!AC:AC,A13),"Equipada", IF( OR(COUNTIFS(Equipar!B:B,3,Equipar!C:C,A13) +COUNTIFS(Equipar!B:B,3,Equipar!D:D,A13) +COUNTIFS(Equipar!B:B,3,Equipar!E:E,A13) +COUNTIFS(Equipar!B:B,3,Equipar!F:F,A13) >0,COUNTIF('Set recomendado'!B:B,C13)=0), "Bloqueada", "Desechable")),"" ) -> Bloqueada | J13: {=IF(ISNUMBER(A13),IFERROR(_xlfn._xlws.FILTER(Equipar!A:A,(Equipar!B:B=3)*(Equipar!AC:AC=A13)),""),"")}
A14: 75 | B14: Legendario | C14: Sentido agudo | D14: Saque | E14: Ataque rápido | F14: Espíritu | G14: Saque | H14: Técnica ofensiva | I14: =IF(ISNUMBER(A14), IF(COUNTIFS(Equipar!B:B,3,Equipar!AC:AC,A14),"Equipada", IF( OR(COUNTIFS(Equipar!B:B,3,Equipar!C:C,A14) +COUNTIFS(Equipar!B:B,3,Equipar!D:D,A14) +COUNTIFS(Equipar!B:B,3,Equipar!E:E,A14) +COUNTIFS(Equipar!B:B,3,Equipar!F:F,A14) >0,COUNTIF('Set recomendado'!B:B,C14)=0), "Bloqueada", "Desechable")),"" ) -> Equipada | J14: {=IF(ISNUMBER(A14),IFERROR(_xlfn._xlws.FILTER(Equipar!A:A,(Equipar!B:B=3)*(Equipar!AC:AC=A14)),""),"")} -> Hinata
A15: 76 | B15: Legendario | C15: Sentido agudo | D15: Saque | E15: Ataque rápido | F15: Técnica defensiva | G15: Recuperación | I15: =IF(ISNUMBER(A15), IF(COUNTIFS(Equipar!B:B,3,Equipar!AC:AC,A15),"Equipada", IF( OR(COUNTIFS(Equipar!B:B,3,Equipar!C:C,A15) +COUNTIFS(Equipar!B:B,3,Equipar!D:D,A15) +COUNTIFS(Equipar!B:B,3,Equipar!E:E,A15) +COUNTIFS(Equipar!B:B,3,Equipar!F:F,A15) >0,COUNTIF('Set recomendado'!B:B,C15)=0), "Bloqueada", "Desechable")),"" ) -> Equipada | J15: {=IF(ISNUMBER(A15),IFERROR(_xlfn._xlws.FILTER(Equipar!A:A,(Equipar!B:B=3)*(Equipar!AC:AC=A15)),""),"")} -> Osamu
A16: 77 | B16: Legendario | C16: Movimiento de bloqueo | D16: Saque | E16: Bloqueo | F16: Colocación | G16: Recepción | H16: Ataque poderoso | I16: =IF(ISNUMBER(A16), IF(COUNTIFS(Equipar!B:B,3,Equipar!AC:AC,A16),"Equipada", IF( OR(COUNTIFS(Equipar!B:B,3,Equipar!C:C,A16) +COUNTIFS(Equipar!B:B,3,Equipar!D:D,A16) +COUNTIFS(Equipar!B:B,3,Equipar!E:E,A16) +COUNTIFS(Equipar!B:B,3,Equipar!F:F,A16) >0,COUNTIF('Set recomendado'!B:B,C16)=0), "Bloqueada", "Desechable")),"" ) -> Desechable | J16: {=IF(ISNUMBER(A16),IFERROR(_xlfn._xlws.FILTER(Equipar!A:A,(Equipar!B:B=3)*(Equipar!AC:AC=A16)),""),"")}
A17: 78 | B17: Legendario | C17: Movimiento de bloqueo | D17: Saque | E17: Recepción | F17: Ataque poderoso | G17: Bloqueo | I17: =IF(ISNUMBER(A17), IF(COUNTIFS(Equipar!B:B,3,Equipar!AC:AC,A17),"Equipada", IF( OR(COUNTIFS(Equipar!B:B,3,Equipar!C:C,A17) +COUNTIFS(Equipar!B:B,3,Equipar!D:D,A17) +COUNTIFS(Equipar!B:B,3,Equipar!E:E,A17) +COUNTIFS(Equipar!B:B,3,Equipar!F:F,A17) >0,COUNTIF('Set recomendado'!B:B,C17)=0), "Bloqueada", "Desechable")),"" ) -> Desechable | J17: {=IF(ISNUMBER(A17),IFERROR(_xlfn._xlws.FILTER(Equipar!A:A,(Equipar!B:B=3)*(Equipar!AC:AC=A17)),""),"")}
A18: 102 | B18: Épico | C18: Bloque preciso | D18: Saque | E18: Recuperación | F18: Bloqueo | G18: Saque | I18: =IF(ISNUMBER(A18), IF(COUNTIFS(Equipar!B:B,3,Equipar!AC:AC,A18),"Equipada", IF( OR(COUNTIFS(Equipar!B:B,3,Equipar!C:C,A18) +COUNTIFS(Equipar!B:B,3,Equipar!D:D,A18) +COUNTIFS(Equipar!B:B,3,Equipar!E:E,A18) +COUNTIFS(Equipar!B:B,3,Equipar!F:F,A18) >0,COUNTIF('Set recomendado'!B:B,C18)=0), "Bloqueada", "Desechable")),"" ) -> Desechable | J18: {=IF(ISNUMBER(A18),IFERROR(_xlfn._xlws.FILTER(Equipar!A:A,(Equipar!B:B=3)*(Equipar!AC:AC=A18)),""),"")}
A19: 105 | B19: Épico | C19: Bloque preciso | D19: Saque | E19: Reflejos | F19: Saque | G19: Bloqueo | I19: =IF(ISNUMBER(A19), IF(COUNTIFS(Equipar!B:B,3,Equipar!AC:AC,A19),"Equipada", IF( OR(COUNTIFS(Equipar!B:B,3,Equipar!C:C,A19) +COUNTIFS(Equipar!B:B,3,Equipar!D:D,A19) +COUNTIFS(Equipar!B:B,3,Equipar!E:E,A19) +COUNTIFS(Equipar!B:B,3,Equipar!F:F,A19) >0,COUNTIF('Set recomendado'!B:B,C19)=0), "Bloqueada", "Desechable")),"" ) -> Bloqueada | J19: {=IF(ISNUMBER(A19),IFERROR(_xlfn._xlws.FILTER(Equipar!A:A,(Equipar!B:B=3)*(Equipar!AC:AC=A19)),""),"")}
A20: 119 | B20: Épico | C20: Movimiento de bloqueo | D20: Saque | E20: Ataque rápido | F20: Bloqueo | G20: Colocación | H20: Colocación | I20: =IF(ISNUMBER(A20), IF(COUNTIFS(Equipar!B:B,3,Equipar!AC:AC,A20),"Equipada", IF( OR(COUNTIFS(Equipar!B:B,3,Equipar!C:C,A20) +COUNTIFS(Equipar!B:B,3,Equipar!D:D,A20) +COUNTIFS(Equipar!B:B,3,Equipar!E:E,A20) +COUNTIFS(Equipar!B:B,3,Equipar!F:F,A20) >0,COUNTIF('Set recomendado'!B:B,C20)=0), "Bloqueada", "Desechable")),"" ) -> Desechable | J20: {=IF(ISNUMBER(A20),IFERROR(_xlfn._xlws.FILTER(Equipar!A:A,(Equipar!B:B=3)*(Equipar!AC:AC=A20)),""),"")}
A21: 120 | B21: Legendario | C21: Recepción de asistencia | D21: Saque | E21: Saque | F21: Fuerza | G21: Bloqueo | H21: Ataque poderoso | I21: =IF(ISNUMBER(A21), IF(COUNTIFS(Equipar!B:B,3,Equipar!AC:AC,A21),"Equipada", IF( OR(COUNTIFS(Equipar!B:B,3,Equipar!C:C,A21) +COUNTIFS(Equipar!B:B,3,Equipar!D:D,A21) +COUNTIFS(Equipar!B:B,3,Equipar!E:E,A21) +COUNTIFS(Equipar!B:B,3,Equipar!F:F,A21) >0,COUNTIF('Set recomendado'!B:B,C21)=0), "Bloqueada", "Desechable")),"" ) -> Desechable | J21: {=IF(ISNUMBER(A21),IFERROR(_xlfn._xlws.FILTER(Equipar!A:A,(Equipar!B:B=3)*(Equipar!AC:AC=A21)),""),"")}
A22: 121 | B22: Legendario | C22: Recepción suprema | D22: Saque | E22: Recepción | F22: Saque | G22: Ataque rápido | I22: =IF(ISNUMBER(A22), IF(COUNTIFS(Equipar!B:B,3,Equipar!AC:AC,A22),"Equipada", IF( OR(COUNTIFS(Equipar!B:B,3,Equipar!C:C,A22) +COUNTIFS(Equipar!B:B,3,Equipar!D:D,A22) +COUNTIFS(Equipar!B:B,3,Equipar!E:E,A22) +COUNTIFS(Equipar!B:B,3,Equipar!F:F,A22) >0,COUNTIF('Set recomendado'!B:B,C22)=0), "Bloqueada", "Desechable")),"" ) -> Desechable | J22: {=IF(ISNUMBER(A22),IFERROR(_xlfn._xlws.FILTER(Equipar!A:A,(Equipar!B:B=3)*(Equipar!AC:AC=A22)),""),"")}
A23: 122 | B23: Legendario | C23: Recepción suprema | D23: Saque | E23: Recepción | F23: Colocación | G23: Ataque poderoso | H23: Técnica ofensiva | I23: =IF(ISNUMBER(A23), IF(COUNTIFS(Equipar!B:B,3,Equipar!AC:AC,A23),"Equipada", IF( OR(COUNTIFS(Equipar!B:B,3,Equipar!C:C,A23) +COUNTIFS(Equipar!B:B,3,Equipar!D:D,A23) +COUNTIFS(Equipar!B:B,3,Equipar!E:E,A23) +COUNTIFS(Equipar!B:B,3,Equipar!F:F,A23) >0,COUNTIF('Set recomendado'!B:B,C23)=0), "Bloqueada", "Desechable")),"" ) -> Equipada | J23: {=IF(ISNUMBER(A23),IFERROR(_xlfn._xlws.FILTER(Equipar!A:A,(Equipar!B:B=3)*(Equipar!AC:AC=A23)),""),"")} -> Kita
A24: 137 | B24: Épico | C24: Recepción de asistencia | D24: Saque | E24: Ataque poderoso | F24: Ataque poderoso | I24: =IF(ISNUMBER(A24), IF(COUNTIFS(Equipar!B:B,3,Equipar!AC:AC,A24),"Equipada", IF( OR(COUNTIFS(Equipar!B:B,3,Equipar!C:C,A24) +COUNTIFS(Equipar!B:B,3,Equipar!D:D,A24) +COUNTIFS(Equipar!B:B,3,Equipar!E:E,A24) +COUNTIFS(Equipar!B:B,3,Equipar!F:F,A24) >0,COUNTIF('Set recomendado'!B:B,C24)=0), "Bloqueada", "Desechable")),"" ) -> Bloqueada | J24: {=IF(ISNUMBER(A24),IFERROR(_xlfn._xlws.FILTER(Equipar!A:A,(Equipar!B:B=3)*(Equipar!AC:AC=A24)),""),"")}
